Workbook
Name SegmentaciónDeDatos_Días_Visita: #N/A
Name SegmentaciónDeDatos_Modo_de_Compra: #N/A
Name SegmentaciónDeDatos_Parque_Origen: #N/A

Sheet Comisiones HEROIC
A1: Parque Origen | B1: Comisión | E1: Precio por día | F1: Hotel
A2: Puente Roto | B2: 12 | E2: 105 | F2: OI Hotels
A3: Monte Japón | B3: 16 | E3: 110 | F3: Elton Hotel
A4: Rio de Castores | B4: 13 | E4: 100 | F4: Ridossan Hotel
A5: Piedra Angular | B5: 25 | E5: 115 | F5: Haiit Hotel
A6: Villa Parque | B6: 22 | E6: 75 | F6: Ski Inn
A7: El cielo | B7: 14
A8: Cascadas Congeladas | B8: 14
A9: Rio Vinoblanco | B9: 16
A10: Molinos Blancos | B10: 24
A11: Montaña Rio Rojo | B11: 17

Sheet Ventas Pases
A1: Momento de Compra | B1: Año | C1: Fecha Compra | D1: Modo de Compra | E1: Fecha Inicial de Pase | F1: Días Visita | G1: Parque Origen | H1: Numero de Pase | I1: Precio Venta | J1: Costo x dia | K1: Hotel | L1: Comisiones | M1: Dias de regalo | N1: Renta | O1: Costos lift
A2: Temporada Regular | B2: 2019 | C2: 43471 | D2: En Línea | E2: 43537 | F2: 9 | G2: Valle Silbador | H2: WSP-0001 | I2: 1080 | J2: =IFERROR('Ventas Pases'!$I2/'Ventas Pases'!$F2,"PASE") -> 120 | K2: =IFERROR(VLOOKUP('Ventas Pases'!$J2,'Comisiones HEROIC'!$E$1:$F$6,2,0),"") | L2: =IF('Ventas Pases'!$D2="Red HEROIC",IFERROR(VLOOKUP('Ventas Pases'!$G2,'Comisiones HEROIC'!$A$1:$B$11,2,0),15),IF('Ventas Pases'!$D2="Red HEROIC",15,0)) -> 0 | M2: =IF(pases[[#This Row],[Días Visita]]<7,0,IF(pases[[#This Row],[Días Visita]]<9,1,IF(pases[[#This Row],[Días Visita]]="Ilimitados",0,2))) -> 2 | N2: =IF(AND('Ventas Pases'!$A2="Fuera de Temporada",'Ventas Pases'!$B2=2019,pases[[#This Row],[Modo de Compra]]="Paquete"),30,0) -> 0 | O2: =-SUMIF(lift[Número de pase],pases[[#This Row],[Numero de Pase]],lift[Costo]) -> 0
A3: Temporada Regular | B3: 2019 | C3: 43427 | D3: En Línea | E3: 43419 | F3: Ilimitados | G3: Valle Silbador | H3: WSP-0002 | I3: 1950 | J3: =IFERROR('Ventas Pases'!$I3/'Ventas Pases'!$F3,"PASE") -> PASE | K3: =IFERROR(VLOOKUP('Ventas Pases'!$J3,'Comisiones HEROIC'!$E$1:$F$6,2,0),"") | L3: =IF('Ventas Pases'!$D3="Red HEROIC",IFERROR(VLOOKUP('Ventas Pases'!$G3,'Comisiones HEROIC'!$A$1:$B$11,2,0),15),IF('Ventas Pases'!$D3="Red HEROIC",15,0)) -> 0 | M3: =IF(pases[[#This Row],[Días Visita]]<7,0,IF(pases[[#This Row],[Días Visita]]<9,1,IF(pases[[#This Row],[Días Visita]]="Ilimitados",0,2))) -> 0 | N3: =IF(AND('Ventas Pases'!$A3="Fuera de Temporada",'Ventas Pases'!$B3=2019,pases[[#This Row],[Modo de Compra]]="Paquete"),30,0) -> 0 | O3: =-SUMIF(lift[Número de pase],pases[[#This Row],[Numero de Pase]],lift[Costo]) -> -368
A4: Fuera de Temporada | B4: 2018 | C4: 43396 | D4: Red HEROIC | E4: 42834 | F4: 6 | G4: Puente Roto | H4: WSP-0003 | I4: 840 | J4: =IFERROR('Ventas Pases'!$I4/'Ventas Pases'!$F4,"PASE") -> 140 | K4: =IFERROR(VLOOKUP('Ventas Pases'!$J4,'Comisiones HEROIC'!$E$1:$F$6,2,0),"") | L4: =IF('Ventas Pases'!$D4="Red HEROIC",IFERROR(VLOOKUP('Ventas Pases'!$G4,'Comisiones HEROIC'!$A$1:$B$11,2,0),15),IF('Ventas Pases'!$D4="Red HEROIC",15,0)) -> 12 | M4: =IF(pases[[#This Row],[Días Visita]]<7,0,IF(pases[[#This Row],[Días Visita]]<9,1,IF(pases[[#This Row],[Días Visita]]="Ilimitados",0,2))) -> 0 | N4: =IF(AND('Ventas Pases'!$A4="Fuera de Temporada",'Ventas Pases'!$B4=2019,pases[[#This Row],[Modo de Compra]]="Paquete"),30,0) -> 0 | O4: =-SUMIF(lift[Número de pase],pases[[#This Row],[Numero de Pase]],lift[Costo]) -> 0
A5: Temporada Regular | B5: 2018 | C5: 43429 | D5: Paquete | E5: 43125 | F5: 7 | G5: Valle Silbador | H5: WSP-0004 | I5: 805 | J5: =IFERROR('Ventas Pases'!$I5/'Ventas Pases'!$F5,"PASE") -> 115 | K5: =IFERROR(VLOOKUP('Ventas Pases'!$J5,'Comisiones HEROIC'!$E$1:$F$6,2,0),"") -> Haiit Hotel | L5: =IF('Ventas Pases'!$D5="Red HEROIC",IFERROR(VLOOKUP('Ventas Pases'!$G5,'Comisiones HEROIC'!$A$1:$B$11,2,0),15),IF('Ventas Pases'!$D5="Red HEROIC",15,0)) -> 0 | M5: =IF(pases[[#This Row],[Días Visita]]<7,0,IF(pases[[#This Row],[Días Visita]]<9,1,IF(pases[[#This Row],[Días Visita]]="Ilimitados",0,2))) -> 1 | N5: =IF(AND('Ventas Pases'!$A5="Fuera de Temporada",'Ventas Pases'!$B5=2019,pases[[#This Row],[Modo de Compra]]="Paquete"),30,0) -> 0 | O5: =-SUMIF(lift[Número de pase],pases[[#This Row],[Numero de Pase]],lift[Costo]) -> 0
A6: Temporada Regular | B6: 2019 | C6: 43429 | D6: Red HEROIC | E6: 43492 | F6: 3 | G6: Montaña Panadero | H6: WSP-0005 | I6: 420 | J6: =IFERROR('Ventas Pases'!$I6/'Ventas Pases'!$F6,"PASE") -> 140 | K6: =IFERROR(VLOOKUP('Ventas Pases'!$J6,'Comisiones HEROIC'!$E$1:$F$6,2,0),"") | L6: =IF('Ventas Pases'!$D6="Red HEROIC",IFERROR(VLOOKUP('Ventas Pases'!$G6,'Comisiones HEROIC'!$A$1:$B$11,2,0),15),IF('Ventas Pases'!$D6="Red HEROIC",15,0)) -> 15 | M6: =IF(pases[[#This Row],[Días Visita]]<7,0,IF(pases[[#This Row],[Días Visita]]<9,1,IF(pases[[#This Row],[Días Visita]]="Ilimitados",0,2))) -> 0 | N6: =IF(AND('Ventas Pases'!$A6="Fuera de Temporada",'Ventas Pases'!$B6=2019,pases[[#This Row],[Modo de Compra]]="Paquete"),30,0) -> 0 | O6: =-SUMIF(lift[Número de pase],pases[[#This Row],[Numero de Pase]],lift[Costo]) -> 0
A7: Fuera de Temporada | B7: 2018 | C7: 43270 | D7: En Línea | E7: 42833 | F7: 2 | G7: Valle Silbador | H7: WSP-0006 | I7: 240 | J7: =IFERROR('Ventas Pases'!$I7/'Ventas Pases'!$F7,"PASE") -> 120 | K7: =IFERROR(VLOOKUP('Ventas Pases'!$J7,'Comisiones HEROIC'!$E$1:$F$6,2,0),"") | L7: =IF('Ventas Pases'!$D7="Red HEROIC",IFERROR(VLOOKUP('Ventas Pases'!$G7,'Comisiones HEROIC'!$A$1:$B$11,2,0),15),IF('Ventas Pases'!$D7="Red HEROIC",15,0)) -> 0 | M7: =IF(pases[[#This Row],[Días Visita]]<7,0,IF(pases[[#This Row],[Días Visita]]<9,1,IF(pases[[#This Row],[Días Visita]]="Ilimitados",0,2))) -> 0 | N7: =IF(AND('Ventas Pases'!$A7="Fuera de Temporada",'Ventas Pases'!$B7=2019,pases[[#This Row],[Modo de Compra]]="Paquete"),30,0) -> 0 | O7: =-SUMIF(lift[Número de pase],pases[[#This Row],[Numero de Pase]],lift[Costo]) -> 0
A8: Temporada Regular | B8: 2018 | C8: 43439 | D8: Paquete | E8: 43148 | F8: 4 | G8: Valle Silbador | H8: WSP-0007 | I8: 300 | J8: =IFERROR('Ventas Pases'!$I8/'Ventas Pases'!$F8,"PASE") -> 75 | K8: =IFERROR(VLOOKUP('Ventas Pases'!$J8,'Comisiones HEROIC'!$E$1:$F$6,2,0),"") -> Ski Inn | L8: =IF('Ventas Pases'!$D8="Red HEROIC",IFERROR(VLOOKUP('Ventas Pases'!$G8,'Comisiones HEROIC'!$A$1:$B$11,2,0),15),IF('Ventas Pases'!$D8="Red HEROIC",15,0)) -> 0 | M8: =IF(pases[[#This Row],[Días Visita]]<7,0,IF(pases[[#This Row],[Días Visita]]<9,1,IF(pases[[#This Row],[Días Visita]]="Ilimitados",0,2))) -> 0 | N8: =IF(AND('Ventas Pases'!$A8="Fuera de Temporada",'Ventas Pases'!$B8=2019,pases[[#This Row],[Modo de Compra]]="Paquete"),30,0) -> 0 | O8: =-SUMIF(lift[Número de pase],pases[[#This Row],[Numero de Pase]],lift[Costo]) -> 0
A9: Fuera de Temporada | B9: 2019 | C9: 43227 | D9: Paquete | E9: 43233 | F9: 6 | G9: Valle Silbador | H9: WSP-0008 | I9: 660 | J9: =IFERROR('Ventas Pases'!$I9/'Ventas Pases'!$F9,"PASE") -> 110 | K9: =IFERROR(VLOOKUP('Ventas Pases'!$J9,'Comisiones HEROIC'!$E$1:$F$6,2,0),"") -> Elton Hotel | L9: =IF('Ventas Pases'!$D9="Red HEROIC",IFERROR(VLOOKUP('Ventas Pases'!$G9,'Comisiones HEROIC'!$A$1:$B$11,2,0),15),IF('Ventas Pases'!$D9="Red HEROIC",15,0)) -> 0 | M9: =IF(pases[[#This Row],[Días Visita]]<7,0,IF(pases[[#This Row],[Días Visita]]<9,1,IF(pases[[#This Row],[Días Visita]]="Ilimitados",0,2))) -> 0 | N9: =IF(AND('Ventas Pases'!$A9="Fuera de Temporada",'Ventas Pases'!$B9=2019,pases[[#This Row],[Modo de Compra]]="Paquete"),30,0) -> 30 | O9: =-SUMIF(lift[Número de pase],pases[[#This Row],[Numero de Pase]],lift[Costo]) -> 0
A10: Temporada Regular | B10: 2019 | C10: 43508 | D10: En Línea | E10: 43508 | F10: 4 | G10: Valle Silbador | H10: WSP-0009 | I10: 480 | J10: =IFERROR('Ventas Pases'!$I10/'Ventas Pases'!$F10,"PASE") -> 120 | K10: =IFERROR(VLOOKUP('Ventas Pases'!$J10,'Comisiones HEROIC'!$E$1:$F$6,2,0),"") | L10: =IF('Ventas Pases'!$D10="Red HEROIC",IFERROR(VLOOKUP('Ventas Pases'!$G10,'Comisiones HEROIC'!$A$1:$B$11,2,0),15),IF('Ventas Pases'!$D10="Red HEROIC",15,0)) -> 0 | M10: =IF(pases[[#This Row],[Días Visita]]<7,0,IF(pases[[#This Row],[Días Visita]]<9,1,IF(pases[[#This Row],[Días Visita]]="Ilimitados",0,2))) -> 0 | N10: =IF(AND('Ventas Pases'!$A10="Fuera de Temporada",'Ventas Pases'!$B10=2019,pases[[#This Row],[Modo de Compra]]="Paquete"),30,0) -> 0 | O10: =-SUMIF(lift[Número de pase],pases[[#This Row],[Numero de Pase]],lift[Costo]) -> 0
A11: Temporada Regular | B11: 2019 | C11: 43547 | D11: En Línea | E11: 43419 | F11: Ilimitados | G11: Valle Silbador | H11: WSP-0010 | I11: 1950 | J11: =IFERROR('Ventas Pases'!$I11/'Ventas Pases'!$F11,"PASE") -> PASE | K11: =IFERROR(VLOOKUP('Ventas Pases'!$J11,'Comisiones HEROIC'!$E$1:$F$6,2,0),"") | L11: =IF('Ventas Pases'!$D11="Red HEROIC",IFERROR(VLOOKUP('Ventas Pases'!$G11,'Comisiones HEROIC'!$A$1:$B$11,2,0),15),IF('Ventas Pases'!$D11="Red HEROIC",15,0)) -> 0 | M11: =IF(pases[[#This Row],[Días Visita]]<7,0,IF(pases[[#This Row],[Días Visita]]<9,1,IF(pases[[#This Row],[Días Visita]]="Ilimitados",0,2))) -> 0 | N11: =IF(AND('Ventas Pases'!$A11="Fuera de Temporada",'Ventas Pases'!$B11=2019,pases[[#This Row],[Modo de Compra]]="Paquete"),30,0) -> 0 | O11: =-SUMIF(lift[Número de pase],pases[[#This Row],[Numero de Pase]],lift[Costo]) -> -368
A12: Temporada Regular | B12: 2019 | C12: 43494 | D12: En Línea | E12: 43504 | F12: 5 | G12: Valle Silbador | H12: WSP-0011 | I12: 600 | J12: =IFERROR('Ventas Pases'!$I12/'Ventas Pases'!$F12,"PASE") -> 120 | K12: =IFERROR(VLOOKUP('Ventas Pases'!$J12,'Comisiones HEROIC'!$E$1:$F$6,2,0),"") | L12: =IF('Ventas Pases'!$D12="Red HEROIC",IFERROR(VLOOKUP('Ventas Pases'!$G12,'Comisiones HEROIC'!$A$1:$B$11,2,0),15),IF('Ventas Pases'!$D12="Red HEROIC",15,0)) -> 0 | M12: =IF(pases[[#This Row],[Días Visita]]<7,0,IF(pases[[#This Row],[Días Visita]]<9,1,IF(pases[[#This Row],[Días Visita]]="Ilimitados",0,2))) -> 0 | N12: =IF(AND('Ventas Pases'!$A12="Fuera de Temporada",'Ventas Pases'!$B12=2019,pases[[#This Row],[Modo de Compra]]="Paquete"),30,0) -> 0 | O12: =-SUMIF(lift[Número de pase],pases[[#This Row],[Numero de Pase]],lift[Costo]) -> 0
A13: Fuera de Temporada | B13: 2019 | C13: 43262 | D13: Red HEROIC | E13: 43225 | F13: 9 | G13: Ski Comanche | H13: WSP-0012 | I13: 1260 | J13: =IFERROR('Ventas Pases'!$I13/'Ventas Pases'!$F13,"PASE") -> 140 | K13: =IFERROR(VLOOKUP('Ventas Pases'!$J13,'Comisiones HEROIC'!$E$1:$F$6,2,0),"") | L13: =IF('Ventas Pases'!$D13="Red HEROIC",IFERROR(VLOOKUP('Ventas Pases'!$G13,'Comisiones HEROIC'!$A$1:$B$11,2,0),15),IF('Ventas Pases'!$D13="Red HEROIC",15,0)) -> 15 | M13: =IF(pases[[#This Row],[Días Visita]]<7,0,IF(pases[[#This Row],[Días Visita]]<9,1,IF(pases[[#This Row],[Días Visita]]="Ilimitados",0,2))) -> 2 | N13: =IF(AND('Ventas Pases'!$A13="Fuera de Temporada",'Ventas Pases'!$B13=2019,pases[[#This Row],[Modo de Compra]]="Paquete"),30,0) -> 0 | O13: =-SUMIF(lift[Número de pase],pases[[#This Row],[Numero de Pase]],lift[Costo]) -> 0
A14: Temporada Regular | B14: 2018 | C14: 43428 | D14: Paquete | E14: 43061 | F14: 3 | G14: Valle Silbador | H14: WSP-0013 | I14: 330 | J14: =IFERROR('Ventas Pases'!$I14/'Ventas Pases'!$F14,"PASE") -> 110 | K14: =IFERROR(VLOOKUP('Ventas Pases'!$J14,'Comisiones HEROIC'!$E$1:$F$6,2,0),"") -> Elton Hotel | L14: =IF('Ventas Pases'!$D14="Red HEROIC",IFERROR(VLOOKUP('Ventas Pases'!$G14,'Comisiones HEROIC'!$A$1:$B$11,2,0),15),IF('Ventas Pases'!$D14="Red HEROIC",15,0)) -> 0 | M14: =IF(pases[[#This Row],[Días Visita]]<7,0,IF(pases[[#This Row],[Días Visita]]<9,1,IF(pases[[#This Row],[Días Visita]]="Ilimitados",0,2))) -> 0 | N14: =IF(AND('Ventas Pases'!$A14="Fuera de Temporada",'Ventas Pases'!$B14=2019,pases[[#This Row],[Modo de Compra]]="Paquete"),30,0) -> 0 | O14: =-SUMIF(lift[Número de pase],pases[[#This Row],[Numero de Pase]],lift[Costo]) -> 0
A15: Temporada Regular | B15: 2019 | C15: 43504 | D15: Paquete | E15: 43501 | F15: 9 | G15: Valle Silbador | H15: WSP-0014 | I15: 945 | J15: =IFERROR('Ventas Pases'!$I15/'Ventas Pases'!$F15,"PASE") -> 105 | K15: =IFERROR(VLOOKUP('Ventas Pases'!$J15,'Comisiones HEROIC'!$E$1:$F$6,2,0),"") -> OI Hotels | L15: =IF('Ventas Pases'!$D15="Red HEROIC",IFERROR(VLOOKUP('Ventas Pases'!$G15,'Comisiones HEROIC'!$A$1:$B$11,2,0),15),IF('Ventas Pases'!$D15="Red HEROIC",15,0)) -> 0 | M15: =IF(pases[[#This Row],[Días Visita]]<7,0,IF(pases[[#This Row],[Días Visita]]<9,1,IF(pases[[#This Row],[Días Visita]]="Ilimitados",0,2))) -> 2 | N15: =IF(AND('Ventas Pases'!$A15="Fuera de Temporada",'Ventas Pases'!$B15=2019,pases[[#This Row],[Modo de Compra]]="Paquete"),30,0) -> 0 | O15: =-SUMIF(lift[Número de pase],pases[[#This Row],[Numero de Pase]],lift[Costo]) -> 0
A16: Temporada Regular | B16: 2018 | C16: 43158 | D16: Paquete | E16: 43171 | F16: 3 | G16: Valle Silbador | H16: WSP-0015 | I16: 330 | J16: =IFERROR('Ventas Pases'!$I16/'Ventas Pases'!$F16,"PASE") -> 110 | K16: =IFERROR(VLOOKUP('Ventas Pases'!$J16,'Comisiones HEROIC'!$E$1:$F$6,2,0),"") -> Elton Hotel | L16: =IF('Ventas Pases'!$D16="Red HEROIC",IFERROR(VLOOKUP('Ventas Pases'!$G16,'Comisiones HEROIC'!$A$1:$B$11,2,0),15),IF('Ventas Pases'!$D16="Red HEROIC",15,0)) -> 0 | M16: =IF(pases[[#This Row],[Días Visita]]<7,0,IF(pases[[#This Row],[Días Visita]]<9,1,IF(pases[[#This Row],[Días Visita]]="Ilimitados",0,2))) -> 0 | N16: =IF(AND('Ventas Pases'!$A16="Fuera de Temporada",'Ventas Pases'!$B16=2019,pases[[#This Row],[Modo de Compra]]="Paquete"),30,0) -> 0 | O16: =-SUMIF(lift[Número de pase],pases[[#This Row],[Numero de Pase]],lift[Costo]) -> 0
A17: Temporada Regular | B17: 2018 | C17: 43435 | D17: En Línea | E17: 43144 | F17: 5 | G17: Valle Silbador | H17: WSP-0016 | I17: 600 | J17: =IFERROR('Ventas Pases'!$I17/'Ventas Pases'!$F17,"PASE") -> 120 | K17: =IFERROR(VLOOKUP('Ventas Pases'!$J17,'Comisiones HEROIC'!$E$1:$F$6,2,0),"") | L17: =IF('Ventas Pases'!$D17="Red HEROIC",IFERROR(VLOOKUP('Ventas Pases'!$G17,'Comisiones HEROIC'!$A$1:$B$11,2,0),15),IF('Ventas Pases'!$D17="Red HEROIC",15,0)) -> 0 | M17: =IF(pases[[#This Row],[Días Visita]]<7,0,IF(pases[[#This Row],[Días Visita]]<9,1,IF(pases[[#This Row],[Días Visita]]="Ilimitados",0,2))) -> 0 | N17: =IF(AND('Ventas Pases'!$A17="Fuera de Temporada",'Ventas Pases'!$B17=2019,pases[[#This Row],[Modo de Compra]]="Paquete"),30,0) -> 0 | O17: =-SUMIF(lift[Número de pase],pases[[#This Row],[Numero de Pase]],lift[Costo]) -> 0
A18: Temporada Regular | B18: 2019 | C18: 43476 | D18: Red HEROIC | E18: 43483 | F18: 3 | G18: Cresta Velo | H18: WSP-0017 | I18: 420 | J18: =IFERROR('Ventas Pases'!$I18/'Ventas Pases'!$F18,"PASE") -> 140 | K18: =IFERROR(VLOOKUP('Ventas Pases'!$J18,'Comisiones HEROIC'!$E$1:$F$6,2,0),"") | L18: =IF('Ventas Pases'!$D18="Red HEROIC",IFERROR(VLOOKUP('Ventas Pases'!$G18,'Comisiones HEROIC'!$A$1:$B$11,2,0),15),IF('Ventas Pases'!$D18="Red HEROIC",15,0)) -> 15 | M18: =IF(pases[[#This Row],[Días Visita]]<7,0,IF(pases[[#This Row],[Días Visita]]<9,1,IF(pases[[#This Row],[Días Visita]]="Ilimitados",0,2))) -> 0 | N18: =IF(AND('Ventas Pases'!$A18="Fuera de Temporada",'Ventas Pases'!$B18=2019,pases[[#This Row],[Modo de Compra]]="Paquete"),30,0) -> 0 | O18: =-SUMIF(lift[Número de pase],pases[[#This Row],[Numero de Pase]],lift[Costo]) -> 0
A19: Temporada Regular | B19: 2018 | C19: 43439 | D19: Red HEROIC | E19: 43078 | F19: 5 | G19: Monte Japón | H19: WSP-0018 | I19: 700 | J19: =IFERROR('Ventas Pases'!$I19/'Ventas Pases'!$F19,"PASE") -> 140 | K19: =IFERROR(VLOOKUP('Ventas Pases'!$J19,'Comisiones HEROIC'!$E$1:$F$6,2,0),"") | L19: =IF('Ventas Pases'!$D19="Red HEROIC",IFERROR(VLOOKUP('Ventas Pases'!$G19,'Comisiones HEROIC'!$A$1:$B$11,2,0),15),IF('Ventas Pases'!$D19="Red HEROIC",15,0)) -> 16 | M19: =IF(pases[[#This Row],[Días Visita]]<7,0,IF(pases[[#This Row],[Días Visita]]<9,1,IF(pases[[#This Row],[Días Visita]]="Ilimitados",0,2))) -> 0 | N19: =IF(AND('Ventas Pases'!$A19="Fuera de Temporada",'Ventas Pases'!$B19=2019,pases[[#This Row],[Modo de Compra]]="Paquete"),30,0) -> 0 | O19: =-SUMIF(lift[Número de pase],pases[[#This Row],[Numero de Pase]],lift[Costo]) -> 0
A20: Temporada Regular | B20: 2018 | C20: 43462 | D20: En Línea | E20: 43113 | F20: 3 | G20: Valle Silbador | H20: WSP-0019 | I20: 360 | J20: =IFERROR('Ventas Pases'!$I20/'Ventas Pases'!$F20,"PASE") -> 120 | K20: =IFERROR(VLOOKUP('Ventas Pases'!$J20,'Comisiones HEROIC'!$E$1:$F$6,2,0),"") | L20: =IF('Ventas Pases'!$D20="Red HEROIC",IFERROR(VLOOKUP('Ventas Pases'!$G20,'Comisiones HEROIC'!$A$1:$B$11,2,0),15),IF('Ventas Pases'!$D20="Red HEROIC",15,0)) -> 0 | M20: =IF(pases[[#This Row],[Días Visita]]<7,0,IF(pases[[#This Row],[Días Visita]]<9,1,IF(pases[[#This Row],[Días Visita]]="Ilimitados",0,2))) -> 0 | N20: =IF(AND('Ventas Pases'!$A20="Fuera de Temporada",'Ventas Pases'!$B20=2019,pases[[#This Row],[Modo de Compra]]="Paquete"),30,0) -> 0 | O20: =-SUMIF(lift[Número de pase],pases[[#This Row],[Numero de Pase]],lift[Costo]) -> 0
A21: Fuera de Temporada | B21: 2018 | C21: 43376 | D21: En Línea | E21: 43054 | F21: Ilimitados | G21: Valle Silbador | H21: WSP-0020 | I21: 1950 | J21: =IFERROR('Ventas Pases'!$I21/'Ventas Pases'!$F21,"PASE") -> PASE | K21: =IFERROR(VLOOKUP('Ventas Pases'!$J21,'Comisiones HEROIC'!$E$1:$F$6,2,0),"") | L21: =IF('Ventas Pases'!$D21="Red HEROIC",IFERROR(VLOOKUP('Ventas Pases'!$G21,'Comisiones HEROIC'!$A$1:$B$11,2,0),15),IF('Ventas Pases'!$D21="Red HEROIC",15,0)) -> 0 | M21: =IF(pases[[#This Row],[Días Visita]]<7,0,IF(pases[[#This Row],[Días Visita]]<9,1,IF(pases[[#This Row],[Días Visita]]="Ilimitados",0,2))) -> 0 | N21: =IF(AND('Ventas Pases'!$A21="Fuera de Temporada",'Ventas Pases'!$B21=2019,pases[[#This Row],[Modo de Compra]]="Paquete"),30,0) -> 0 | O21: =-SUMIF(lift[Número de pase],pases[[#This Row],[Numero de Pase]],lift[Costo]) -> -276
A22: Temporada Regular | B22: 2019 | C22: 43511 | D22: En Línea | E22: 43419 | F22: Ilimitados | G22: Valle Silbador | H22: WSP-0021 | I22: 1950 | J22: =IFERROR('Ventas Pases'!$I22/'Ventas Pases'!$F22,"PASE") -> PASE | K22: =IFERROR(VLOOKUP('Ventas Pases'!$J22,'Comisiones HEROIC'!$E$1:$F$6,2,0),"") | L22: =IF('Ventas Pases'!$D22="Red HEROIC",IFERROR(VLOOKUP('Ventas Pases'!$G22,'Comisiones HEROIC'!$A$1:$B$11,2,0),15),IF('Ventas Pases'!$D22="Red HEROIC",15,0)) -> 0 | M22: =IF(pases[[#This Row],[Días Visita]]<7,0,IF(pases[[#This Row],[Días Visita]]<9,1,IF(pases[[#This Row],[Días Visita]]="Ilimitados",0,2))) -> 0 | N22: =IF(AND('Ventas Pases'!$A22="Fuera de Temporada",'Ventas Pases'!$B22=2019,pases[[#This Row],[Modo de Compra]]="Paquete"),30,0) -> 0 | O22: =-SUMIF(lift[Número de pase],pases[[#This Row],[Numero de Pase]],lift[Costo]) -> -920
A23: Fuera de Temporada | B23: 2019 | C23: 43318 | D23: Paquete | E23: 43202 | F23: 6 | G23: Valle Silbador | H23: WSP-0022 | I23: 660 | J23: =IFERROR('Ventas Pases'!$I23/'Ventas Pases'!$F23,"PASE") -> 110 | K23: =IFERROR(VLOOKUP('Ventas Pases'!$J23,'Comisiones HEROIC'!$E$1:$F$6,2,0),"") -> Elton Hotel | L23: =IF('Ventas Pases'!$D23="Red HEROIC",IFERROR(VLOOKUP('Ventas Pases'!$G23,'Comisiones HEROIC'!$A$1:$B$11,2,0),15),IF('Ventas Pases'!$D23="Red HEROIC",15,0)) -> 0 | M23: =IF(pases[[#This Row],[Días Visita]]<7,0,IF(pases[[#This Row],[Días Visita]]<9,1,IF(pases[[#This Row],[Días Visita]]="Ilimitados",0,2))) -> 0 | N23: =IF(AND('Ventas Pases'!$A23="Fuera de Temporada",'Ventas Pases'!$B23=2019,pases[[#This Row],[Modo de Compra]]="Paquete"),30,0) -> 30 | O23: =-SUMIF(lift[Número de pase],pases[[#This Row],[Numero de Pase]],lift[Costo]) -> 0
A24: Temporada Regular | B24: 2019 | C24: 43421 | D24: Red HEROIC | E24: 43433 | F24: 6 | G24: Cresta Velo | H24: WSP-0023 | I24: 840 | J24: =IFERROR('Ventas Pases'!$I24/'Ventas Pases'!$F24,"PASE") -> 140 | K24: =IFERROR(VLOOKUP('Ventas Pases'!$J24,'Comisiones HEROIC'!$E$1:$F$6,2,0),"") | L24: =IF('Ventas Pases'!$D24="Red HEROIC",IFERROR(VLOOKUP('Ventas Pases'!$G24,'Comisiones HEROIC'!$A$1:$B$11,2,0),15),IF('Ventas Pases'!$D24="Red HEROIC",15,0)) -> 15 | M24: =IF(pases[[#This Row],[Días Visita]]<7,0,IF(pases[[#This Row],[Días Visita]]<9,1,IF(pases[[#This Row],[Días Visita]]="Ilimitados",0,2))) -> 0 | N24: =IF(AND('Ventas Pases'!$A24="Fuera de Temporada",'Ventas Pases'!$B24=2019,pases[[#This Row],[Modo de Compra]]="Paquete"),30,0) -> 0 | O24: =-SUMIF(lift[Número de pase],pases[[#This Row],[Numero de Pase]],lift[Costo]) -> 0
A25: Temporada Regular | B25: 2018 | C25: 43142 | D25: En Línea | E25: 43054 | F25: Ilimitados | G25: Valle Silbador | H25: WSP-0024 | I25: 1950 | J25: =IFERROR('Ventas Pases'!$I25/'Ventas Pases'!$F25,"PASE") -> PASE | K25: =IFERROR(VLOOKUP('Ventas Pases'!$J25,'Comisiones HEROIC'!$E$1:$F$6,2,0),"") | L25: =IF('Ventas Pases'!$D25="Red HEROIC",IFERROR(VLOOKUP('Ventas Pases'!$G25,'Comisiones HEROIC'!$A$1:$B$11,2,0),15),IF('Ventas Pases'!$D25="Red HEROIC",15,0)) -> 0 | M25: =IF(pases[[#This Row],[Días Visita]]<7,0,IF(pases[[#This Row],[Días Visita]]<9,1,IF(pases[[#This Row],[Días Visita]]="Ilimitados",0,2))) -> 0 | N25: =IF(AND('Ventas Pases'!$A25="Fuera de Temporada",'Ventas Pases'!$B25=2019,pases[[#This Row],[Modo de Compra]]="Paquete"),30,0) -> 0 | O25: =-SUMIF(lift[Número de pase],pases[[#This Row],[Numero de Pase]],lift[Costo]) -> -828
A26: Temporada Regular | B26: 2018 | C26: 43457 | D26: Paquete | E26: 43125 | F26: 9 | G26: Valle Silbador | H26: WSP-0025 | I26: 900 | J26: =IFERROR('Ventas Pases'!$I26/'Ventas Pases'!$F26,"PASE") -> 100 | K26: =IFERROR(VLOOKUP('Ventas Pases'!$J26,'Comisiones HEROIC'!$E$1:$F$6,2,0),"") -> Ridossan Hotel | L26: =IF('Ventas Pases'!$D26="Red HEROIC",IFERROR(VLOOKUP('Ventas Pases'!$G26,'Comisiones HEROIC'!$A$1:$B$11,2,0),15),IF('Ventas Pases'!$D26="Red HEROIC",15,0)) -> 0 | M26: =IF(pases[[#This Row],[Días Visita]]<7,0,IF(pases[[#This Row],[Días Visita]]<9,1,IF(pases[[#This Row],[Días Visita]]="Ilimitados",0,2))) -> 2 | N26: =IF(AND('Ventas Pases'!$A26="Fuera de Temporada",'Ventas Pases'!$B26=2019,pases[[#This Row],[Modo de Compra]]="Paquete"),30,0) -> 0 | O26: =-SUMIF(lift[Número de pase],pases[[#This Row],[Numero de Pase]],lift[Costo]) -> 0
A27: Fuera de Temporada | B27: 2018 | C27: 43331 | D27: En Línea | E27: 43054 | F27: Ilimitados | G27: Valle Silbador | H27: WSP-0026 | I27: 1950 | J27: =IFERROR('Ventas Pases'!$I27/'Ventas Pases'!$F27,"PASE") -> PASE | K27: =IFERROR(VLOOKUP('Ventas Pases'!$J27,'Comisiones HEROIC'!$E$1:$F$6,2,0),"") | L27: =IF('Ventas Pases'!$D27="Red HEROIC",IFERROR(VLOOKUP('Ventas Pases'!$G27,'Comisiones HEROIC'!$A$1:$B$11,2,0),15),IF('Ventas Pases'!$D27="Red HEROIC",15,0)) -> 0 | M27: =IF(pases[[#This Row],[Días Visita]]<7,0,IF(pases[[#This Row],[Días Visita]]<9,1,IF(pases[[#This Row],[Días Visita]]="Ilimitados",0,2))) -> 0 | N27: =IF(AND('Ventas Pases'!$A27="Fuera de Temporada",'Ventas Pases'!$B27=2019,pases[[#This Row],[Modo de Compra]]="Paquete"),30,0) -> 0 | O27: =-SUMIF(lift[Número de pase],pases[[#This Row],[Numero de Pase]],lift[Costo]) -> -368
A28: Temporada Regular | B28: 2018 | C28: 43449 | D28: En Línea | E28: 43054 | F28: Ilimitados | G28: Valle Silbador | H28: WSP-0027 | I28: 1950 | J28: =IFERROR('Ventas Pases'!$I28/'Ventas Pases'!$F28,"PASE") -> PASE | K28: =IFERROR(VLOOKUP('Ventas Pases'!$J28,'Comisiones HEROIC'!$E$1:$F$6,2,0),"") | L28: =IF('Ventas Pases'!$D28="Red HEROIC",IFERROR(VLOOKUP('Ventas Pases'!$G28,'Comisiones HEROIC'!$A$1:$B$11,2,0),15),IF('Ventas Pases'!$D28="Red HEROIC",15,0)) -> 0 | M28: =IF(pases[[#This Row],[Días Visita]]<7,0,IF(pases[[#This Row],[Días Visita]]<9,1,IF(pases[[#This Row],[Días Visita]]="Ilimitados",0,2))) -> 0 | N28: =IF(AND('Ventas Pases'!$A28="Fuera de Temporada",'Ventas Pases'!$B28=2019,pases[[#This Row],[Modo de Compra]]="Paquete"),30,0) -> 0 | O28: =-SUMIF(lift[Número de pase],pases[[#This Row],[Numero de Pase]],lift[Costo]) -> -460
A29: Fuera de Temporada | B29: 2019 | C29: 43384 | D29: Paquete | E29: 43244 | F29: 6 | G29: Valle Silbador | H29: WSP-0028 | I29: 660 | J29: =IFERROR('Ventas Pases'!$I29/'Ventas Pases'!$F29,"PASE") -> 110 | K29: =IFERROR(VLOOKUP('Ventas Pases'!$J29,'Comisiones HEROIC'!$E$1:$F$6,2,0),"") -> Elton Hotel | L29: =IF('Ventas Pases'!$D29="Red HEROIC",IFERROR(VLOOKUP('Ventas Pases'!$G29,'Comisiones HEROIC'!$A$1:$B$11,2,0),15),IF('Ventas Pases'!$D29="Red HEROIC",15,0)) -> 0 | M29: =IF(pases[[#This Row],[Días Visita]]<7,0,IF(pases[[#This Row],[Días Visita]]<9,1,IF(pases[[#This Row],[Días Visita]]="Ilimitados",0,2))) -> 0 | N29: =IF(AND('Ventas Pases'!$A29="Fuera de Temporada",'Ventas Pases'!$B29=2019,pases[[#This Row],[Modo de Compra]]="Paquete"),30,0) -> 30 | O29: =-SUMIF(lift[Número de pase],pases[[#This Row],[Numero de Pase]],lift[Costo]) -> 0
A30: Temporada Regular | B30: 2019 | C30: 43428 | D30: En Línea | E30: 43419 | F30: Ilimitados | G30: Valle Silbador | H30: WSP-0029 | I30: 1950 | J30: =IFERROR('Ventas Pases'!$I30/'Ventas Pases'!$F30,"PASE") -> PASE | K30: =IFERROR(VLOOKUP('Ventas Pases'!$J30,'Comisiones HEROIC'!$E$1:$F$6,2,0),"") | L30: =IF('Ventas Pases'!$D30="Red HEROIC",IFERROR(VLOOKUP('Ventas Pases'!$G30,'Comisiones HEROIC'!$A$1:$B$11,2,0),15),IF('Ventas Pases'!$D30="Red HEROIC",15,0)) -> 0 | M30: =IF(pases[[#This Row],[Días Visita]]<7,0,IF(pases[[#This Row],[Días Visita]]<9,1,IF(pases[[#This Row],[Días Visita]]="Ilimitados",0,2))) -> 0 | N30: =IF(AND('Ventas Pases'!$A30="Fuera de Temporada",'Ventas Pases'!$B30=2019,pases[[#This Row],[Modo de Compra]]="Paquete"),30,0) -> 0 | O30: =-SUMIF(lift[Número de pase],pases[[#This Row],[Numero de Pase]],lift[Costo]) -> -460
A31: Temporada Regular | B31: 2019 | C31: 43452 | D31: En Línea | E31: 43449 | F31: 7 | G31: Valle Silbador | H31: WSP-0030 | I31: 840 | J31: =IFERROR('Ventas Pases'!$I31/'Ventas Pases'!$F31,"PASE") -> 120 | K31: =IFERROR(VLOOKUP('Ventas Pases'!$J31,'Comisiones HEROIC'!$E$1:$F$6,2,0),"") | L31: =IF('Ventas Pases'!$D31="Red HEROIC",IFERROR(VLOOKUP('Ventas Pases'!$G31,'Comisiones HEROIC'!$A$1:$B$11,2,0),15),IF('Ventas Pases'!$D31="Red HEROIC",15,0)) -> 0 | M31: =IF(pases[[#This Row],[Días Visita]]<7,0,IF(pases[[#This Row],[Días Visita]]<9,1,IF(pases[[#This Row],[Días Visita]]="Ilimitados",0,2))) -> 1 | N31: =IF(AND('Ventas Pases'!$A31="Fuera de Temporada",'Ventas Pases'!$B31=2019,pases[[#This Row],[Modo de Compra]]="Paquete"),30,0) -> 0 | O31: =-SUMIF(lift[Número de pase],pases[[#This Row],[Numero de Pase]],lift[Costo]) -> 0
A32: Temporada Regular | B32: 2019 | C32: 43517 | D32: Paquete | E32: 43541 | F32: 6 | G32: Valle Silbador | H32: WSP-0031 | I32: 660 | J32: =IFERROR('Ventas Pases'!$I32/'Ventas Pases'!$F32,"PASE") -> 110 | K32: =IFERROR(VLOOKUP('Ventas Pases'!$J32,'Comisiones HEROIC'!$E$1:$F$6,2,0),"") -> Elton Hotel | L32: =IF('Ventas Pases'!$D32="Red HEROIC",IFERROR(VLOOKUP('Ventas Pases'!$G32,'Comisiones HEROIC'!$A$1:$B$11,2,0),15),IF('Ventas Pases'!$D32="Red HEROIC",15,0)) -> 0 | M32: =IF(pases[[#This Row],[Días Visita]]<7,0,IF(pases[[#This Row],[Días Visita]]<9,1,IF(pases[[#This Row],[Días Visita]]="Ilimitados",0,2))) -> 0 | N32: =IF(AND('Ventas Pases'!$A32="Fuera de Temporada",'Ventas Pases'!$B32=2019,pases[[#This Row],[Modo de Compra]]="Paquete"),30,0) -> 0 | O32: =-SUMIF(lift[Número de pase],pases[[#This Row],[Numero de Pase]],lift[Costo]) -> 0
A33: Temporada Regular | B33: 2019 | C33: 43449 | D33: Paquete | E33: 43532 | F33: 4 | G33: Valle Silbador | H33: WSP-0032 | I33: 400 | J33: =IFERROR('Ventas Pases'!$I33/'Ventas Pases'!$F33,"PASE") -> 100 | K33: =IFERROR(VLOOKUP('Ventas Pases'!$J33,'Comisiones HEROIC'!$E$1:$F$6,2,0),"") -> Ridossan Hotel | L33: =IF('Ventas Pases'!$D33="Red HEROIC",IFERROR(VLOOKUP('Ventas Pases'!$G33,'Comisiones HEROIC'!$A$1:$B$11,2,0),15),IF('Ventas Pases'!$D33="Red HEROIC",15,0)) -> 0 | M33: =IF(pases[[#This Row],[Días Visita]]<7,0,IF(pases[[#This Row],[Días Visita]]<9,1,IF(pases[[#This Row],[Días Visita]]="Ilimitados",0,2))) -> 0 | N33: =IF(AND('Ventas Pases'!$A33="Fuera de Temporada",'Ventas Pases'!$B33=2019,pases[[#This Row],[Modo de Compra]]="Paquete"),30,0) -> 0 | O33: =-SUMIF(lift[Número de pase],pases[[#This Row],[Numero de Pase]],lift[Costo]) -> 0
A34: Fuera de Temporada | B34: 2019 | C34: 43268 | D34: En Línea | E34: 43266 | F34: 9 | G34: Valle Silbador | H34: WSP-0033 | I34: 1080 | J34: =IFERROR('Ventas Pases'!$I34/'Ventas Pases'!$F34,"PASE") -> 120 | K34: =IFERROR(VLOOKUP('Ventas Pases'!$J34,'Comisiones HEROIC'!$E$1:$F$6,2,0),"") | L34: =IF('Ventas Pases'!$D34="Red HEROIC",IFERROR(VLOOKUP('Ventas Pases'!$G34,'Comisiones HEROIC'!$A$1:$B$11,2,0),15),IF('Ventas Pases'!$D34="Red HEROIC",15,0)) -> 0 | M34: =IF(pases[[#This Row],[Días Visita]]<7,0,IF(pases[[#This Row],[Días Visita]]<9,1,IF(pases[[#This Row],[Días Visita]]="Ilimitados",0,2))) -> 2 | N34: =IF(AND('Ventas Pases'!$A34="Fuera de Temporada",'Ventas Pases'!$B34=2019,pases[[#This Row],[Modo de Compra]]="Paquete"),30,0) -> 0 | O34: =-SUMIF(lift[Número de pase],pases[[#This Row],[Numero de Pase]],lift[Costo]) -> 0
A35: Fuera de Temporada | B35: 2018 | C35: 43298 | D35: Red HEROIC | E35: 42851 | F35: 4 | G35: Cresta Velo | H35: WSP-0034 | I35: 560 | J35: =IFERROR('Ventas Pases'!$I35/'Ventas Pases'!$F35,"PASE") -> 140 | K35: =IFERROR(VLOOKUP('Ventas Pases'!$J35,'Comisiones HEROIC'!$E$1:$F$6,2,0),"") | L35: =IF('Ventas Pases'!$D35="Red HEROIC",IFERROR(VLOOKUP('Ventas Pases'!$G35,'Comisiones HEROIC'!$A$1:$B$11,2,0),15),IF('Ventas Pases'!$D35="Red HEROIC",15,0)) -> 15 | M35: =IF(pases[[#This Row],[Días Visita]]<7,0,IF(pases[[#This Row],[Días Visita]]<9,1,IF(pases[[#This Row],[Días Visita]]="Ilimitados",0,2))) -> 0 | N35: =IF(AND('Ventas Pases'!$A35="Fuera de Temporada",'Ventas Pases'!$B35=2019,pases[[#This Row],[Modo de Compra]]="Paquete"),30,0) -> 0 | O35: =-SUMIF(lift[Número de pase],pases[[#This Row],[Numero de Pase]],lift[Costo]) -> 0
A36: Temporada Regular | B36: 2018 | C36: 43107 | D36: Red HEROIC | E36: 43121 | F36: 5 | G36: Puente Roto | H36: WSP-0035 | I36: 700 | J36: =IFERROR('Ventas Pases'!$I36/'Ventas Pases'!$F36,"PASE") -> 140 | K36: =IFERROR(VLOOKUP('Ventas Pases'!$J36,'Comisiones HEROIC'!$E$1:$F$6,2,0),"") | L36: =IF('Ventas Pases'!$D36="Red HEROIC",IFERROR(VLOOKUP('Ventas Pases'!$G36,'Comisiones HEROIC'!$A$1:$B$11,2,0),15),IF('Ventas Pases'!$D36="Red HEROIC",15,0)) -> 12 | M36: =IF(pases[[#This Row],[Días Visita]]<7,0,IF(pases[[#This Row],[Días Visita]]<9,1,IF(pases[[#This Row],[Días Visita]]="Ilimitados",0,2))) -> 0 | N36: =IF(AND('Ventas Pases'!$A36="Fuera de Temporada",'Ventas Pases'!$B36=2019,pases[[#This Row],[Modo de Compra]]="Paquete"),30,0) -> 0 | O36: =-SUMIF(lift[Número de pase],pases[[#This Row],[Numero de Pase]],lift[Costo]) -> 0
A37: Temporada Regular | B37: 2019 | C37: 43554 | D37: En Línea | E37: 43546 | F37: 7 | G37: Valle Silbador | H37: WSP-0036 | I37: 840 | J37: =IFERROR('Ventas Pases'!$I37/'Ventas Pases'!$F37,"PASE") -> 120 | K37: =IFERROR(VLOOKUP('Ventas Pases'!$J37,'Comisiones HEROIC'!$E$1:$F$6,2,0),"") | L37: =IF('Ventas Pases'!$D37="Red HEROIC",IFERROR(VLOOKUP('Ventas Pases'!$G37,'Comisiones HEROIC'!$A$1:$B$11,2,0),15),IF('Ventas Pases'!$D37="Red HEROIC",15,0)) -> 0 | M37: =IF(pases[[#This Row],[Días Visita]]<7,0,IF(pases[[#This Row],[Días Visita]]<9,1,IF(pases[[#This Row],[Días Visita]]="Ilimitados",0,2))) -> 1 | N37: =IF(AND('Ventas Pases'!$A37="Fuera de Temporada",'Ventas Pases'!$B37=2019,pases[[#This Row],[Modo de Compra]]="Paquete"),30,0) -> 0 | O37: =-SUMIF(lift[Número de pase],pases[[#This Row],[Numero de Pase]],lift[Costo]) -> 0
A38: Temporada Regular | B38: 2019 | C38: 43479 | D38: Paquete | E38: 43525 | F38: 8 | G38: Valle Silbador | H38: WSP-0037 | I38: 880 | J38: =IFERROR('Ventas Pases'!$I38/'Ventas Pases'!$F38,"PASE") -> 110 | K38: =IFERROR(VLOOKUP('Ventas Pases'!$J38,'Comisiones HEROIC'!$E$1:$F$6,2,0),"") -> Elton Hotel | L38: =IF('Ventas Pases'!$D38="Red HEROIC",IFERROR(VLOOKUP('Ventas Pases'!$G38,'Comisiones HEROIC'!$A$1:$B$11,2,0),15),IF('Ventas Pases'!$D38="Red HEROIC",15,0)) -> 0 | M38: =IF(pases[[#This Row],[Días Visita]]<7,0,IF(pases[[#This Row],[Días Visita]]<9,1,IF(pases[[#This Row],[Días Visita]]="Ilimitados",0,2))) -> 1 | N38: =IF(AND('Ventas Pases'!$A38="Fuera de Temporada",'Ventas Pases'!$B38=2019,pases[[#This Row],[Modo de Compra]]="Paquete"),30,0) -> 0 | O38: =-SUMIF(lift[Número de pase],pases[[#This Row],[Numero de Pase]],lift[Costo]) -> 0
A39: Temporada Regular | B39: 2019 | C39: 43555 | D39: En Línea | E39: 43419 | F39: Ilimitados | G39: Valle Silbador | H39: WSP-0038 | I39: 1950 | J39: =IFERROR('Ventas Pases'!$I39/'Ventas Pases'!$F39,"PASE") -> PASE | K39: =IFERROR(VLOOKUP('Ventas Pases'!$J39,'Comisiones HEROIC'!$E$1:$F$6,2,0),"") | L39: =IF('Ventas Pases'!$D39="Red HEROIC",IFERROR(VLOOKUP('Ventas Pases'!$G39,'Comisiones HEROIC'!$A$1:$B$11,2,0),15),IF('Ventas Pases'!$D39="Red HEROIC",15,0)) -> 0 | M39: =IF(pases[[#This Row],[Días Visita]]<7,0,IF(pases[[#This Row],[Días Visita]]<9,1,IF(pases[[#This Row],[Días Visita]]="Ilimitados",0,2))) -> 0 | N39: =IF(AND('Ventas Pases'!$A39="Fuera de Temporada",'Ventas Pases'!$B39=2019,pases[[#This Row],[Modo de Compra]]="Paquete"),30,0) -> 0 | O39: =-SUMIF(lift[Número de pase],pases[[#This Row],[Numero de Pase]],lift[Costo]) -> -552
A40: Temporada Regular | B40: 2018 | C40: 43120 | D40: Red HEROIC | E40: 43173 | F40: 1 | G40: Puente Roto | H40: WSP-0039 | I40: 140 | J40: =IFERROR('Ventas Pases'!$I40/'Ventas Pases'!$F40,"PASE") -> 140 | K40: =IFERROR(VLOOKUP('Ventas Pases'!$J40,'Comisiones HEROIC'!$E$1:$F$6,2,0),"") | L40: =IF('Ventas Pases'!$D40="Red HEROIC",IFERROR(VLOOKUP('Ventas Pases'!$G40,'Comisiones HEROIC'!$A$1:$B$11,2,0),15),IF('Ventas Pases'!$D40="Red HEROIC",15,0)) -> 12 | M40: =IF(pases[[#This Row],[Días Visita]]<7,0,IF(pases[[#This Row],[Días Visita]]<9,1,IF(pases[[#This Row],[Días Visita]]="Ilimitados",0,2))) -> 0 | N40: =IF(AND('Ventas Pases'!$A40="Fuera de Temporada",'Ventas Pases'!$B40=2019,pases[[#This Row],[Modo de Compra]]="Paquete"),30,0) -> 0 | O40: =-SUMIF(lift[Número de pase],pases[[#This Row],[Numero de Pase]],lift[Costo]) -> 0
...

Sheet Lifts Semana
A1: Fecha | B1: Hora | C1: Día de la semana | D1: Telesqui (Lift) | E1: Número de pase | F1: Costo
A2: 43423 | B2: 0.52 | C2: Lunes | D2: Góndola Principal | E2: WSP-12651 | F2: 92
A3: 43490 | B3: 0.14 | C3: Viernes | D3: Montaña Negra | E3: WSP-0386 | F3: 92
A4: 43532 | B4: 0.15 | C4: Viernes | D4: Montaña Negra | E4: WSP-14941 | F4: 92
A5: 43549 | B5: 0.12 | C5: Lunes | D5: Valle Silbador | E5: WSP-9787 | F5: 92
A6: 43507 | B6: 0.74 | C6: Lunes | D6: Riachuelo Caliente | E6: WSP-14455 | F6: 92
A7: 43536 | B7: 0.91 | C7: Martes | D7: Góndola Principal | E7: WSP-11595 | F7: 92
A8: 43501 | B8: 0.1 | C8: Martes | D8: Montaña Negra | E8: WSP-17836 | F8: 92
A9: 43444 | B9: 0.63 | C9: Lunes | D9: Cima del mundo | E9: WSP-18970 | F9: 92
A10: 43538 | B10: 0.29 | C10: Jueves | D10: Montaña Negra | E10: WSP-14285 | F10: 92
A11: 43444 | B11: 0.21 | C11: Lunes | D11: Montaña Negra | E11: WSP-9047 | F11: 92
A12: 43546 | B12: 0.64 | C12: Viernes | D12: Valle Silbador | E12: WSP-0444 | F12: 92
A13: 43538 | B13: 0.01 | C13: Jueves | D13: Valle Silbador | E13: WSP-4652 | F13: 92
... A12497: 43446 | B12497: 0.39 | C12497: Miércoles | D12497: Valle Silbador | E12497: WSP-0331 | F12497: 92

Sheet Analisis
A1: Análisis de pases
A2: Ventas totales | F2: Visitantes por modo de compra | J2: Días Visita | K2: 7
A3: Suma de Precio Venta | F3: Etiquetas de fila | G3: Cuenta de Momento de Compra
A4: 4078035 | B4: =GETPIVOTDATA("Precio Venta",$A$3) -> 4078035 | F4: En Línea | G4: 0.49269854 | J4: Suma de Dias de regalo
F5: Red HEROIC | G5: 0.25245049 | J5: 451
F6: Paquete | G6: 0.17903581
A7: Promedio de visita | F7: Físico | G7: 0.075815163
A8: Días Visita | B8: (Varios elementos) | F8: Total general | G8: 1
A10: Promedio de Días Visita
A11: 4.9905727 | B11: =GETPIVOTDATA("Días Visita",$A$10) -> 4.9905727 | F11: Visitantes por parque Red HEORIC | J11: Cuenta de Fecha | K11: Etiquetas de columna
F12: Modo de Compra | G12: Red HEROIC | J12: Etiquetas de fila | K12: Cima del mundo | L12: Góndola Principal | M12: Montaña Negra | N12: Riachuelo Caliente | O12: Valle Silbador | P12: Total general
A13: Ventas mayores a $1000 | J13: Trim.1 | K13: 509 | L13: 1518 | M13: 2408 | N13: 823 | O13: 2843 | P13: 8101
F14: Etiquetas de fila | G14: Cuenta de Momento de Compra | J14: Trim.2 | K14: 1 | L14: 19 | M14: 23 | N14: 7 | O14: 30 | P14: 80
F15: Monte Japón | G15: 0.049920761 | J15: Trim.4 | K15: 263 | L15: 879 | M15: 1307 | N15: 390 | O15: 1476 | P15: 4315
A16: Etiquetas de fila | B16: Suma de Precio Venta | F16: Ski Comanche | G16: 0.11014263 | J16: Total general | K16: 773 | L16: 2416 | M16: 3738 | N16: 1220 | O16: 4349 | P16: 12496
A17: <1000 | B17: 2004270 | C17: =GETPIVOTDATA("Precio Venta",$A$16,"Precio Venta",1000) -> 2073765 | F17: Puente Roto | G17: 0.22028526
A18: 1000-1999 | B18: 2073765 | C18: =GETPIVOTDATA("Precio Venta",$A$16,"Precio Venta",1000)/B4 -> 0.50852065 | F18: Cresta Velo | G18: 0.27020602
A19: Total general | B19: 4078035 | F19: Montaña Panadero | G19: 0.34944532
F20: Total general | G20: 1
A22: Dias de regalo
A23: Suma de Dias de regalo | F23: Viajes en lift por trimestre
A24: 1892 | B24: =GETPIVOTDATA("Dias de regalo",$A$23) -> 1892
F26: Etiquetas de fila | G26: Cuenta de Fecha
A27: Rentas | F27: Trim.1 | G27: 8101
A28: Suma de Renta | F28: Trim.2 | G28: 80
A29: 3780 | B29: =GETPIVOTDATA("Renta",$A$28) -> 3780 | F29: Trim.4 | G29: 4315
F30: Total general | G30: 12496
A32: Ganancia
A33: Días Visita | B33: Ilimitados
A34: ventas | D34: costos
A35: Suma de Precio Venta | D35: Suma de Costos lift
A36: 1474200 | D36: -284188 | F36: Cuenta de Fecha | G36: Día de la semana
F37: Número de pase | G37: Domingo | H37: Lunes | I37: Martes | J37: Miércoles | K37: Jueves | L37: Viernes | M37: Sábado | N37: Total general
A38: Ganancia | C38: Ganancias/perdidas | F38: WSP-3711 | G38: 4 | H38: 5 | I38: 4 | K38: 2 | L38: 1 | N38: 16
A39: =GETPIVOTDATA("Precio Venta",$A$35)+GETPIVOTDATA("Costos lift",$D$35) -> 1190012 | C39: =A39/-GETPIVOTDATA("Costos lift",$D$35) -> 4.1874112 | F39: WSP-13456 | G39: 1 | H39: 2 | I39: 2 | J39: 4 | K39: 1 | L39: 4 | M39: 1 | N39: 15
F40: WSP-9980 | G40: 4 | I40: 3 | J40: 2 | K40: 2 | L40: 2 | M40: 2 | N40: 15
F41: WSP-9066 | G41: 4 | H41: 3 | I41: 4 | J41: 1 | K41: 1 | L41: 1 | N41: 14
F42: WSP-9241 | G42: 3 | H42: 4 | I42: 2 | J42: 1 | K42: 2 | L42: 1 | M42: 1 | N42: 14
F43: WSP-11590 | G43: 3 | H43: 1 | J43: 1 | K43: 1 | L43: 4 | M43: 3 | N43: 13
F44: WSP-5982 | H44: 1 | I44: 1 | J44: 1 | K44: 3 | L44: 3 | M44: 4 | N44: 13
...

Sheet Dashboard
E13: Ventas por Hotel
E14: Modo de Compra | F14: Paquete
E16: Hotel | F16: Ventas
E17: Elton Hotel | F17: 244200
E18: Haiit Hotel | F18: 8855
E19: OI Hotels | F19: 113190
E20: Ridossan Hotel | F20: 78400
E21: Ski Inn | F21: 17550
E22: Total general | F22: 462195
E26: Comisiones por pagar | H26: Viajes del 33% de los mejores esquiadores
E27: Modo de Compra | F27: Red HEROIC
E29: Parque | F29: Comisión | H29: Dia de la semana | I29: Cantidad
E30: Montaña Panadero | F30: 6615 | H30: Domingo | I30: 620
E31: Cresta Velo | F31: 5115 | H31: Lunes | I31: 604
E32: Puente Roto | F32: 3336 | H32: Martes | I32: 580
E33: Ski Comanche | F33: 2085 | H33: Miércoles | I33: 566
E34: Monte Japón | F34: 1008 | H34: Jueves | I34: 567
E35: Total general | F35: 18159 | H35: Viernes | I35: 584
H36: Sábado | I36: 607
H37: Total | I37: =SUM(I30:I36) -> 4128
C41: Realizado por:
C42: Gabriel Quezada
